Workbook
Name KeyA: 'אבני דרך'!$C$12
Name KeyB: 'אבני דרך'!$D$12
Name M_Key: 'אבני דרך'!$J$5:$J$16
Name M_ID: 'אבני דרך'!$A$5:$A$16
Name M_Name: 'אבני דרך'!$B$5:$B$16
Name M_Date: 'אבני דרך'!$E$5:$E$16
Name T_ID: 'משימות'!$A$5:$A$95
Name T_Phase: 'משימות'!$B$5:$B$95
Name T_Task: 'משימות'!$C$5:$C$95
Name T_Owner: 'משימות'!$D$5:$D$95
Name T_Prio: 'משימות'!$E$5:$E$95
Name T_Status: 'משימות'!$F$5:$F$95
Name T_Eff: 'משימות'!$G$5:$G$95
Name T_Prog: 'משימות'!$I$5:$I$95
Name T_Start: 'משימות'!$J$5:$J$95
Name T_Due: 'משימות'!$K$5:$K$95
Name T_Up: 'משימות'!$V$5:$V$95
Name T_Kan: 'משימות'!$W$5:$W$95
Name T_Ariel: 'משימות'!$X$5:$X$95
Name T_Rinat: 'משימות'!$Y$5:$Y$95
Name T_Tamar: 'משימות'!$Z$5:$Z$95
Name T_Other: 'משימות'!$AA$5:$AA$95
Name Scenario: 'לוח בקרה'!$D$4
Name KeyActual: 'לוח בקרה'!$K$4
Name TodayOverride: 'לוח בקרה'!$N$4
Name Today_: 'לוח בקרה'!$S$4
Name KeyActive: 'לוח בקרה'!$T$4
Name EvictDate: 'לוח בקרה'!$U$4
Name D_No: 'החלטות'!$A$5:$A$16
Name D_Name: 'החלטות'!$B$5:$B$16
Name D_Task: 'החלטות'!$E$5:$E$16
Name D_Due: 'החלטות'!$H$5:$H$16
Name D_Status: 'החלטות'!$I$5:$I$16
Name D_Key: 'החלטות'!$K$5:$K$16

Sheet לוח בקרה
B1: 🏡 בית אלון | מרכז ניהול השיפוץ
B2: ="📆 היום: "&TEXT(Today_,"dd/mm/yyyy")&" · 🎛️ תרחיש פעיל: "&IF(Scenario="B","B — מפתח מאוחר (ינואר)","A — מפתח מוקדם (תחילת דצמבר)")&" · 🔑 מפתח: "&TEXT(KeyActive,"dd/mm/yyyy")&IF(KeyActual<>""," (בפועל)"," (תכנון)")
B4: 🎛️ תרחיש פעיל ▼ | D4: A | E4: =IF(Scenario="B","B: מפתח 5.1.2027 · מגורי ביניים ~חודש + אחסון","A: מפתח 1.12.2026 · נכנסים מיד וגרים בבית בזמן השיפוץ") | I4: 🔑 מפתח בפועל (אם נקבע) | L4: 📅 "היום" לבדיקה (ריק = היום) | O4: ✏️ תאים צהובים = קלט. כל השאר מתעדכן לבד. | S4: =IF(N4<>"",N4,TODAY()) | T4: =IF(KeyActual<>"",KeyActual,IF(Scenario="B",KeyB,KeyA)) | U4: ='אבני דרך'!E9
B6: 📋 סה"כ משימות | D6: ✅ הושלמו | F6: 🔄 בתהליך | H6: ⏰ באיחור | J6: ⛔ תקוע / ממתין | L6: 📈 % השלמה | N6: 🔑 ימים למפתח | P6: 📦 ימים לפינוי
B7: =COUNTIF(T_ID,"?*") | D7: =COUNTIF(T_Status,"הושלם") | F7: =COUNTIF(T_Eff,"בתהליך") | H7: =COUNTIF(T_Eff,"באיחור") | J7: =COUNTIF(T_Eff,"תקוע")+COUNTIF(T_Eff,"ממתין") | L7: =IFERROR(SUMIFS(T_Prog,T_Status,"<>בוטל")/(COUNTIF(T_ID,"?*")-COUNTIF(T_Status,"בוטל")),0) | N7: =KeyActive-Today_ | P7: =IF(EvictDate="","",EvictDate-Today_)
B9: ="פתוחות: "&(COUNTIF(T_ID,"?*")-COUNTIF(T_Status,"הושלם")-COUNTIF(T_Status,"בוטל")) | D9: =TEXT(IFERROR(COUNTIF(T_Status,"הושלם")/COUNTIF(T_ID,"?*"),0),"0%")&" מהמשימות" | F9: ="בעבודה כרגע" | H9: =IF(COUNTIF(T_Eff,"באיחור")>0,"⚠ דורש טיפול","👍 אין איחורים") | J9: ="תקוע: "&COUNTIF(T_Eff,"תקוע")&" · ממתין: "&COUNTIF(T_Eff,"ממתין") | L9: =REPT("█",ROUND(L7*10,0))&REPT("░",10-ROUND(L7*10,0)) | N9: =TEXT(KeyActive,"dd/mm/yyyy")&IF(KeyActual<>""," (בפועל)"," (תרחיש "&Scenario&")") | P9: =IF(EvictDate="","",TEXT(EvictDate,"dd/mm/yyyy")&" · לא אומת")
B11: 📊 התקדמות לפי שלב | K11: 📅 על השולחן — 14 הימים הקרובים (כולל באיחור)
B12: שלב | E12: משימות | F12: הושלמו | G12: פתוחות | H12: % התקדמות | K12: 🎯 יעד | L12: ID | M12: משימה | P12: אחראי | Q12: מצב
B13: 0 איסוף מידע | E13: =COUNTIF(T_Phase,B13) | F13: =COUNTIFS(T_Phase,B13,T_Status,"הושלם") | G13: =E13-F13-COUNTIFS(T_Phase,B13,T_Status,"בוטל") | H13: =IFERROR(SUMIFS(T_Prog,T_Phase,B13,T_Status,"<>בוטל")/(E13-COUNTIFS(T_Phase,B13,T_Status,"בוטל")),0) | K13: =IF($S13="","",INDEX(T_Due,$S13)) | L13: =IF($S13="","",INDEX(T_ID,$S13)) | M13: =IF($S13="","",INDEX(T_Task,$S13)) | P13: =IF($S13="","",INDEX(T_Owner,$S13)) | Q13: =IF($S13="","",INDEX(T_Eff,$S13)) | S13: =IFERROR(MATCH(SMALL(T_Up,1),T_Up,0),"")
B14: 1 היתכנות | E14: =COUNTIF(T_Phase,B14) | F14: =COUNTIFS(T_Phase,B14,T_Status,"הושלם") | G14: =E14-F14-COUNTIFS(T_Phase,B14,T_Status,"בוטל") | H14: =IFERROR(SUMIFS(T_Prog,T_Phase,B14,T_Status,"<>בוטל")/(E14-COUNTIFS(T_Phase,B14,T_Status,"בוטל")),0) | K14: =IF($S14="","",INDEX(T_Due,$S14)) | L14: =IF($S14="","",INDEX(T_ID,$S14)) | M14: =IF($S14="","",INDEX(T_Task,$S14)) | P14: =IF($S14="","",INDEX(T_Owner,$S14)) | Q14: =IF($S14="","",INDEX(T_Eff,$S14)) | S14: =IFERROR(MATCH(SMALL(T_Up,2),T_Up,0),"")
B15: 2 תכנון | E15: =COUNTIF(T_Phase,B15) | F15: =COUNTIFS(T_Phase,B15,T_Status,"הושלם") | G15: =E15-F15-COUNTIFS(T_Phase,B15,T_Status,"בוטל") | H15: =IFERROR(SUMIFS(T_Prog,T_Phase,B15,T_Status,"<>בוטל")/(E15-COUNTIFS(T_Phase,B15,T_Status,"בוטל")),0) | K15: =IF($S15="","",INDEX(T_Due,$S15)) | L15: =IF($S15="","",INDEX(T_ID,$S15)) | M15: =IF($S15="","",INDEX(T_Task,$S15)) | P15: =IF($S15="","",INDEX(T_Owner,$S15)) | Q15: =IF($S15="","",INDEX(T_Eff,$S15)) | S15: =IFERROR(MATCH(SMALL(T_Up,3),T_Up,0),"")
B16: 3 התקשרויות | E16: =COUNTIF(T_Phase,B16) | F16: =COUNTIFS(T_Phase,B16,T_Status,"הושלם") | G16: =E16-F16-COUNTIFS(T_Phase,B16,T_Status,"בוטל") | H16: =IFERROR(SUMIFS(T_Prog,T_Phase,B16,T_Status,"<>בוטל")/(E16-COUNTIFS(T_Phase,B16,T_Status,"בוטל")),0) | K16: =IF($S16="","",INDEX(T_Due,$S16)) | L16: =IF($S16="","",INDEX(T_ID,$S16)) | M16: =IF($S16="","",INDEX(T_Task,$S16)) | P16: =IF($S16="","",INDEX(T_Owner,$S16)) | Q16: =IF($S16="","",INDEX(T_Eff,$S16)) | S16: =IFERROR(MATCH(SMALL(T_Up,4),T_Up,0),"")
B17: 4 שלד ופתחים | E17: =COUNTIF(T_Phase,B17) | F17: =COUNTIFS(T_Phase,B17,T_Status,"הושלם") | G17: =E17-F17-COUNTIFS(T_Phase,B17,T_Status,"בוטל") | H17: =IFERROR(SUMIFS(T_Prog,T_Phase,B17,T_Status,"<>בוטל")/(E17-COUNTIFS(T_Phase,B17,T_Status,"בוטל")),0) | K17: =IF($S17="","",INDEX(T_Due,$S17)) | L17: =IF($S17="","",INDEX(T_ID,$S17)) | M17: =IF($S17="","",INDEX(T_Task,$S17)) | P17: =IF($S17="","",INDEX(T_Owner,$S17)) | Q17: =IF($S17="","",INDEX(T_Eff,$S17)) | S17: =IFERROR(MATCH(SMALL(T_Up,5),T_Up,0),"")
B18: 5 מערכות | E18: =COUNTIF(T_Phase,B18) | F18: =COUNTIFS(T_Phase,B18,T_Status,"הושלם") | G18: =E18-F18-COUNTIFS(T_Phase,B18,T_Status,"בוטל") | H18: =IFERROR(SUMIFS(T_Prog,T_Phase,B18,T_Status,"<>בוטל")/(E18-COUNTIFS(T_Phase,B18,T_Status,"בוטל")),0) | K18: =IF($S18="","",INDEX(T_Due,$S18)) | L18: =IF($S18="","",INDEX(T_ID,$S18)) | M18: =IF($S18="","",INDEX(T_Task,$S18)) | P18: =IF($S18="","",INDEX(T_Owner,$S18)) | Q18: =IF($S18="","",INDEX(T_Eff,$S18)) | S18: =IFERROR(MATCH(SMALL(T_Up,6),T_Up,0),"")
B19: 6 גמר פנים | E19: =COUNTIF(T_Phase,B19) | F19: =COUNTIFS(T_Phase,B19,T_Status,"הושלם") | G19: =E19-F19-COUNTIFS(T_Phase,B19,T_Status,"בוטל") | H19: =IFERROR(SUMIFS(T_Prog,T_Phase,B19,T_Status,"<>בוטל")/(E19-COUNTIFS(T_Phase,B19,T_Status,"בוטל")),0) | K19: =IF($S19="","",INDEX(T_Due,$S19)) | L19: =IF($S19="","",INDEX(T_ID,$S19)) | M19: =IF($S19="","",INDEX(T_Task,$S19)) | P19: =IF($S19="","",INDEX(T_Owner,$S19)) | Q19: =IF($S19="","",INDEX(T_Eff,$S19)) | S19: =IFERROR(MATCH(SMALL(T_Up,7),T_Up,0),"")
B20: 7 חוץ ופיתוח | E20: =COUNTIF(T_Phase,B20) | F20: =COUNTIFS(T_Phase,B20,T_Status,"הושלם") | G20: =E20-F20-COUNTIFS(T_Phase,B20,T_Status,"בוטל") | H20: =IFERROR(SUMIFS(T_Prog,T_Phase,B20,T_Status,"<>בוטל")/(E20-COUNTIFS(T_Phase,B20,T_Status,"בוטל")),0) | K20: =IF($S20="","",INDEX(T_Due,$S20)) | L20: =IF($S20="","",INDEX(T_ID,$S20)) | M20: =IF($S20="","",INDEX(T_Task,$S20)) | P20: =IF($S20="","",INDEX(T_Owner,$S20)) | Q20: =IF($S20="","",INDEX(T_Eff,$S20)) | S20: =IFERROR(MATCH(SMALL(T_Up,8),T_Up,0),"")
B21: 8 ריהוט | E21: =COUNTIF(T_Phase,B21) | F21: =COUNTIFS(T_Phase,B21,T_Status,"הושלם") | G21: =E21-F21-COUNTIFS(T_Phase,B21,T_Status,"בוטל") | H21: =IFERROR(SUMIFS(T_Prog,T_Phase,B21,T_Status,"<>בוטל")/(E21-COUNTIFS(T_Phase,B21,T_Status,"בוטל")),0) | K21: =IF($S21="","",INDEX(T_Due,$S21)) | L21: =IF($S21="","",INDEX(T_ID,$S21)) | M21: =IF($S21="","",INDEX(T_Task,$S21)) | P21: =IF($S21="","",INDEX(T_Owner,$S21)) | Q21: =IF($S21="","",INDEX(T_Eff,$S21)) | S21: =IFERROR(MATCH(SMALL(T_Up,9),T_Up,0),"")
B22: 9 מסירה | E22: =COUNTIF(T_Phase,B22) | F22: =COUNTIFS(T_Phase,B22,T_Status,"הושלם") | G22: =E22-F22-COUNTIFS(T_Phase,B22,T_Status,"בוטל") | H22: =IFERROR(SUMIFS(T_Prog,T_Phase,B22,T_Status,"<>בוטל")/(E22-COUNTIFS(T_Phase,B22,T_Status,"בוטל")),0) | K22: =IF($S22="","",INDEX(T_Due,$S22)) | L22: =IF($S22="","",INDEX(T_ID,$S22)) | M22: =IF($S22="","",INDEX(T_Task,$S22)) | P22: =IF($S22="","",INDEX(T_Owner,$S22)) | Q22: =IF($S22="","",INDEX(T_Eff,$S22)) | S22: =IFERROR(MATCH(SMALL(T_Up,10),T_Up,0),"")
B23: הכנה למעבר | E23: =COUNTIF(T_Phase,B23) | F23: =COUNTIFS(T_Phase,B23,T_Status,"הושלם") | G23: =E23-F23-COUNTIFS(T_Phase,B23,T_Status,"בוטל") | H23: =IFERROR(SUMIFS(T_Prog,T_Phase,B23,T_Status,"<>בוטל")/(E23-COUNTIFS(T_Phase,B23,T_Status,"בוטל")),0) | K23: =IF($S23="","",INDEX(T_Due,$S23)) | L23: =IF($S23="","",INDEX(T_ID,$S23)) | M23: =IF($S23="","",INDEX(T_Task,$S23)) | P23: =IF($S23="","",INDEX(T_Owner,$S23)) | Q23: =IF($S23="","",INDEX(T_Eff,$S23)) | S23: =IFERROR(MATCH(SMALL(T_Up,11),T_Up,0),"")
B24: ניהול | E24: =COUNTIF(T_Phase,B24) | F24: =COUNTIFS(T_Phase,B24,T_Status,"הושלם") | G24: =E24-F24-COUNTIFS(T_Phase,B24,T_Status,"בוטל") | H24: =IFERROR(SUMIFS(T_Prog,T_Phase,B24,T_Status,"<>בוטל")/(E24-COUNTIFS(T_Phase,B24,T_Status,"בוטל")),0) | K24: =IF($S24="","",INDEX(T_Due,$S24)) | L24: =IF($S24="","",INDEX(T_ID,$S24)) | M24: =IF($S24="","",INDEX(T_Task,$S24)) | P24: =IF($S24="","",INDEX(T_Owner,$S24)) | Q24: =IF($S24="","",INDEX(T_Eff,$S24)) | S24: =IFERROR(MATCH(SMALL(T_Up,12),T_Up,0),"")
B25: A: מגורים בזמן שיפוץ | E25: =COUNTIF(T_Phase,B25) | F25: =COUNTIFS(T_Phase,B25,T_Status,"הושלם") | G25: =E25-F25-COUNTIFS(T_Phase,B25,T_Status,"בוטל") | H25: =IFERROR(SUMIFS(T_Prog,T_Phase,B25,T_Status,"<>בוטל")/(E25-COUNTIFS(T_Phase,B25,T_Status,"בוטל")),0) | K25: =IF($S25="","",INDEX(T_Due,$S25)) | L25: =IF($S25="","",INDEX(T_ID,$S25)) | M25: =IF($S25="","",INDEX(T_Task,$S25)) | P25: =IF($S25="","",INDEX(T_Owner,$S25)) | Q25: =IF($S25="","",INDEX(T_Eff,$S25)) | S25: =IFERROR(MATCH(SMALL(T_Up,13),T_Up,0),"")
B26: B: מגורי ביניים | E26: =COUNTIF(T_Phase,B26) | F26: =COUNTIFS(T_Phase,B26,T_Status,"הושלם") | G26: =E26-F26-COUNTIFS(T_Phase,B26,T_Status,"בוטל") | H26: =IFERROR(SUMIFS(T_Prog,T_Phase,B26,T_Status,"<>בוטל")/(E26-COUNTIFS(T_Phase,B26,T_Status,"בוטל")),0) | K26: =IF($S26="","",INDEX(T_Due,$S26)) | L26: =IF($S26="","",INDEX(T_ID,$S26)) | M26: =IF($S26="","",INDEX(T_Task,$S26)) | P26: =IF($S26="","",INDEX(T_Owner,$S26)) | Q26: =IF($S26="","",INDEX(T_Eff,$S26)) | S26: =IFERROR(MATCH(SMALL(T_Up,14),T_Up,0),"")
B27: סה"כ | E27: =SUM(E13:E26) | F27: =SUM(F13:F26) | G27: =SUM(G13:G26) | H27: =L7 | K27: =IF($S27="","",INDEX(T_Due,$S27)) | L27: =IF($S27="","",INDEX(T_ID,$S27)) | M27: =IF($S27="","",INDEX(T_Task,$S27)) | P27: =IF($S27="","",INDEX(T_Owner,$S27)) | Q27: =IF($S27="","",INDEX(T_Eff,$S27)) | S27: =IFERROR(MATCH(SMALL(T_Up,15),T_Up,0),"")
K28: =IF(COUNT(T_Up)>15,"+ עוד "&(COUNT(T_Up)-15)&" משימות פתוחות בחלון — ראו לשונית משימות / לפי אחראי","סה''כ בחלון: "&COUNT(T_Up)&" משימות")
B30: ⚖️ החלטות קריטיות הבאות | K30: 🏁 אבני הדרך הבאות
B31: # | C31: החלטה | G31: משימה | H31: 🎯 יעד | I31: מצב | K31: 📍 תאריך | L31: # | M31: אבן דרך | P31: ⏳ ימים
B32: =IF($T32="","",INDEX(D_No,$T32)) | C32: =IF($T32="","",INDEX(D_Name,$T32)) | G32: =IF($T32="","",INDEX(D_Task,$T32)) | H32: =IF($T32="","",INDEX(D_Due,$T32)) | I32: =IF($T32="","",INDEX(D_Status,$T32)) | K32: =IF($U32="","",INDEX(M_Date,$U32)) | L32: =IF($U32="","",INDEX(M_ID,$U32)) | M32: =IF($U32="","",INDEX(M_Name,$U32)) | P32: =IF($U32="","",INDEX(M_Date,$U32)-Today_) | T32: =IFERROR(MATCH(SMALL(D_Key,1),D_Key,0),"") | U32: =IFERROR(MATCH(SMALL(M_Key,1),M_Key,0),"")
B33: =IF($T33="","",INDEX(D_No,$T33)) | C33: =IF($T33="","",INDEX(D_Name,$T33)) | G33: =IF($T33="","",INDEX(D_Task,$T33)) | H33: =IF($T33="","",INDEX(D_Due,$T33)) | I33: =IF($T33="","",INDEX(D_Status,$T33)) | K33: =IF($U33="","",INDEX(M_Date,$U33)) | L33: =IF($U33="","",INDEX(M_ID,$U33)) | M33: =IF($U33="","",INDEX(M_Name,$U33)) | P33: =IF($U33="","",INDEX(M_Date,$U33)-Today_) | T33: =IFERROR(MATCH(SMALL(D_Key,2),D_Key,0),"") | U33: =IFERROR(MATCH(SMALL(M_Key,2),M_Key,0),"")
B34: =IF($T34="","",INDEX(D_No,$T34)) | C34: =IF($T34="","",INDEX(D_Name,$T34)) | G34: =IF($T34="","",INDEX(D_Task,$T34)) | H34: =IF($T34="","",INDEX(D_Due,$T34)) | I34: =IF($T34="","",INDEX(D_Status,$T34)) | K34: =IF($U34="","",INDEX(M_Date,$U34)) | L34: =IF($U34="","",INDEX(M_ID,$U34)) | M34: =IF($U34="","",INDEX(M_Name,$U34)) | P34: =IF($U34="","",INDEX(M_Date,$U34)-Today_) | T34: =IFERROR(MATCH(SMALL(D_Key,3),D_Key,0),"") | U34: =IFERROR(MATCH(SMALL(M_Key,3),M_Key,0),"")
B35: =IF($T35="","",INDEX(D_No,$T35)) | C35: =IF($T35="","",INDEX(D_Name,$T35)) | G35: =IF($T35="","",INDEX(D_Task,$T35)) | H35: =IF($T35="","",INDEX(D_Due,$T35)) | I35: =IF($T35="","",INDEX(D_Status,$T35)) | K35: =IF($U35="","",INDEX(M_Date,$U35)) | L35: =IF($U35="","",INDEX(M_ID,$U35)) | M35: =IF($U35="","",INDEX(M_Name,$U35)) | P35: =IF($U35="","",INDEX(M_Date,$U35)-Today_) | T35: =IFERROR(MATCH(SMALL(D_Key,4),D_Key,0),"") | U35: =IFERROR(MATCH(SMALL(M_Key,4),M_Key,0),"")
B36: =IF($T36="","",INDEX(D_No,$T36)) | C36: =IF($T36="","",INDEX(D_Name,$T36)) | G36: =IF($T36="","",INDEX(D_Task,$T36)) | H36: =IF($T36="","",INDEX(D_Due,$T36)) | I36: =IF($T36="","",INDEX(D_Status,$T36)) | K36: =IF($U36="","",INDEX(M_Date,$U36)) | L36: =IF($U36="","",INDEX(M_ID,$U36)) | M36: =IF($U36="","",INDEX(M_Name,$U36)) | P36: =IF($U36="","",INDEX(M_Date,$U36)-Today_) | T36: =IFERROR(MATCH(SMALL(D_Key,5),D_Key,0),"") | U36: =IFERROR(MATCH(SMALL(M_Key,5),M_Key,0),"")
B37: =IF($T37="","",INDEX(D_No,$T37)) | C37: =IF($T37="","",INDEX(D_Name,$T37)) | G37: =IF($T37="","",INDEX(D_Task,$T37)) | H37: =IF($T37="","",INDEX(D_Due,$T37)) | I37: =IF($T37="","",INDEX(D_Status,$T37)) | K37: =IF($U37="","",INDEX(M_Date,$U37)) | L37: =IF($U37="","",INDEX(M_ID,$U37)) | M37: =IF($U37="","",INDEX(M_Name,$U37)) | P37: =IF($U37="","",INDEX(M_Date,$U37)-Today_) | T37: =IFERROR(MATCH(SMALL(D_Key,6),D_Key,0),"") | U37: =IFERROR(MATCH(SMALL(M_Key,6),M_Key,0),"")
B39: 📶 גרף התקדמות לפי שלב | K39: 🧩 התפלגות מצב משימות
K40: מצב | L40: כמות
K41: לא התחיל | L41: =COUNTIF(T_Eff,K41)
K42: בתהליך | L42: =COUNTIF(T_Eff,K42)
K43: ממתין | L43: =COUNTIF(T_Eff,K43)
K44: תקוע | L44: =COUNTIF(T_Eff,K44)
K45: באיחור | L45: =COUNTIF(T_Eff,K45)
K46: הושלם | L46: =COUNTIF(T_Eff,K46)
...

Sheet משימות
A1: 📋 משימות — מקור האמת של הפרויקט
A2: עמודות צהובות = לעדכון ידני (סטטוס, עדיפות, % ידני, תאריכים) · ⚡ = מחושב אוטומטית לפי תרחיש ותאריך היום · שורות ריקות בתחתית להוספת משימות
A3: מקרא: | B3: לא התחיל | C3: בתהליך | D3: ממתין | E3: תקוע | F3: באיחור | G3: הושלם | H3: בוטל
A4: ID | B4: שלב | C4: משימה | D4: אחראי | E4: עדיפות | F4: סטטוס | G4: ⚡ מצב מחושב | H4: % ידני | I4: 📈 התקדמות | J4: ▶ התחלה (פעיל) | K4: 🎯 יעד (פעיל) | L4: ⏳ ימים ליעד | M4: תלויות | N4: Mode | O4: התחלה (מוקדם) | P4: יעד (מוקדם) | Q4: התחלה (מאוחר) | R4: יעד (מאוחר) | S4: תיאור | T4: מידע/מסמכים נדרשים | U4: הערות / הנחות | V4: _up | W4: _kan | X4: _ariel | Y4: _rinat | Z4: _tamar | AA4: _other
A5: T-001 | B5: 0 איסוף מידע | C5: החלטת תקציב כולל + רזרבה | D5: אריאל+רינת | E5: גבוהה | F5: לא התחיל | G5: =IF($A5="","",IF(AND(F5<>"הושלם",F5<>"בוטל",K5<>"",K5<Today_),"באיחור",IF(F5="","לא התחיל",F5))) | I5: =IF($A5="","",IF(H5<>"",H5,IF(F5="הושלם",1,IF(F5="בתהליך",0.5,IF(OR(F5="ממתין",F5="תקוע"),0.25,0))))) | J5: =IF(OR($A5="",O5=""),"",IF(AND(N5="K",KeyActual<>""),O5+(KeyActual-KeyA),IF(Scenario="B",IF(Q5="",O5,Q5),O5))) | K5: =IF(OR($A5="",P5=""),"",IF(AND(N5="K",KeyActual<>""),P5+(KeyActual-KeyA),IF(Scenario="B",IF(R5="",P5,R5),P5))) | L5: =IF(OR($A5="",K5=""),"",IF(OR(F5="הושלם",F5="בוטל"),"",K5-Today_)) | M5: — | N5: F | O5: 46310 | P5: 46317 | Q5: 46310 | R5: 46317 | S5: לקבוע תקרת תקציב, רזרבה (המלצה 10–15%, הנחה) וסדר עדיפויות; החלטה #1 | T5: מקורות מימון, משכנתא/הלוואה, תקציב גינה 20–50 אלף (לא אומת) | U5: Decision Log #1 | V5: =IF(AND($A5<>"",F5<>"הושלם",F5<>"בוטל",J5<>""),IF(J5<=Today_+14,IF(K5="",99999,K5)+ROW()/100000,""),"") | W5: =IFERROR(IF($A5="","",CHOOSE(MATCH(G5,{"לא התחיל","בתהליך","ממתין","תקוע","באיחור","הושלם","בוטל"},0),1,2,3,3,4,5,6)*100000+IF(K5="",99999,K5)+ROW()/1000000),"") | X5: =IF(AND($A5<>"",F5<>"הושלם",F5<>"בוטל",OR(ISNUMBER(SEARCH("אריאל",D5)),D5="כל המשפחה")),IF(K5="",99999,K5)+ROW()/100000,"") | Y5: =IF(AND($A5<>"",F5<>"הושלם",F5<>"בוטל",OR(ISNUMBER(SEARCH("רינת",D5)),D5="כל המשפחה")),IF(K5="",99999,K5)+ROW()/100000,"") | Z5: =IF(AND($A5<>"",F5<>"הושלם",F5<>"בוטל",OR(ISNUMBER(SEARCH("תמר",D5)))),IF(K5="",99999,K5)+ROW()/100000,"") | AA5: =IF(AND($A5<>"",F5<>"הושלם",F5<>"בוטל",NOT(ISNUMBER(SEARCH("אריאל",D5))),NOT(ISNUMBER(SEARCH("רינת",D5))),NOT(ISNUMBER(SEARCH("תמר",D5))),D5<>"כל המשפחה"),IF(K5="",99999,K5)+ROW()/100000,"")
A6: T-002 | B6: 0 איסוף מידע | C6: הוחלט: גרים בבית בזמן העבודות (תרחיש A) | D6: אריאל+רינת | E6: גבוהה | F6: הושלם | G6: =IF($A6="","",IF(AND(F6<>"הושלם",F6<>"בוטל",K6<>"",K6<Today_),"באיחור",IF(F6="","לא התחיל",F6))) | I6: =IF($A6="","",IF(H6<>"",H6,IF(F6="הושלם",1,IF(F6="בתהליך",0.5,IF(OR(F6="ממתין",F6="תקוע"),0.25,0))))) | J6: =IF(OR($A6="",O6=""),"",IF(AND(N6="K",KeyActual<>""),O6+(KeyActual-KeyA),IF(Scenario="B",IF(Q6="",O6,Q6),O6))) | K6: =IF(OR($A6="",P6=""),"",IF(AND(N6="K",KeyActual<>""),P6+(KeyActual-KeyA),IF(Scenario="B",IF(R6="",P6,R6),P6))) | L6: =IF(OR($A6="",K6=""),"",IF(OR(F6="הושלם",F6="בוטל"),"",K6-Today_)) | M6: — | N6: F | O6: 46306 | P6: 46306 | Q6: 46306 | R6: 46306 | S6: החלטה #2 התקבלה 11.10: אם המפתח בתחילת דצמבר — נכנסים מיד ומשפצים בשלבים תוך מגורים | U6: הושלם; תרחיש B = מגורי ביניים | V6: =IF(AND($A6<>"",F6<>"הושלם",F6<>"בוטל",J6<>""),IF(J6<=Today_+14,IF(K6="",99999,K6)+ROW()/100000,""),"") | W6: =IFERROR(IF($A6="","",CHOOSE(MATCH(G6,{"לא התחיל","בתהליך","ממתין","תקוע","באיחור","הושלם","בוטל"},0),1,2,3,3,4,5,6)*100000+IF(K6="",99999,K6)+ROW()/1000000),"") | X6: =IF(AND($A6<>"",F6<>"הושלם",F6<>"בוטל",OR(ISNUMBER(SEARCH("אריאל",D6)),D6="כל המשפחה")),IF(K6="",99999,K6)+ROW()/100000,"") | Y6: =IF(AND($A6<>"",F6<>"הושלם",F6<>"בוטל",OR(ISNUMBER(SEARCH("רינת",D6)),D6="כל המשפחה")),IF(K6="",99999,K6)+ROW()/100000,"") | Z6: =IF(AND($A6<>"",F6<>"הושלם",F6<>"בוטל",OR(ISNUMBER(SEARCH("תמר",D6)))),IF(K6="",99999,K6)+ROW()/100000,"") | AA6: =IF(AND($A6<>"",F6<>"הושלם",F6<>"בוטל",NOT(ISNUMBER(SEARCH("אריאל",D6))),NOT(ISNUMBER(SEARCH("רינת",D6))),NOT(ISNUMBER(SEARCH("תמר",D6))),D6<>"כל המשפחה"),IF(K6="",99999,K6)+ROW()/100000,"")
A7: T-003 | B7: 0 איסוף מידע | C7: איסוף תוכניות קבלן/קונסטרוקציה + שרטוטי חצר | D7: אריאל | E7: גבוהה | F7: בתהליך | G7: =IF($A7="","",IF(AND(F7<>"הושלם",F7<>"בוטל",K7<>"",K7<Today_),"באיחור",IF(F7="","לא התחיל",F7))) | I7: =IF($A7="","",IF(H7<>"",H7,IF(F7="הושלם",1,IF(F7="בתהליך",0.5,IF(OR(F7="ממתין",F7="תקוע"),0.25,0))))) | J7: =IF(OR($A7="",O7=""),"",IF(AND(N7="K",KeyActual<>""),O7+(KeyActual-KeyA),IF(Scenario="B",IF(Q7="",O7,Q7),O7))) | K7: =IF(OR($A7="",P7=""),"",IF(AND(N7="K",KeyActual<>""),P7+(KeyActual-KeyA),IF(Scenario="B",IF(R7="",P7,R7),P7))) | L7: =IF(OR($A7="",K7=""),"",IF(OR(F7="הושלם",F7="בוטל"),"",K7-Today_)) | M7: — | N7: F | O7: 46310 | P7: 46320 | Q7: 46310 | R7: 46320 | S7: להעלות לתיקיית source את תוכניות הקבלן, השרטוטים הצבעוניים והיתר קיים | T7: תוכניות, היתר בנייה קיים, חוזה רכישה | U7: חסר כרגע בתיקייה | 11.10: התקבלו מ-Drive תוכניות קבלן (דגם תמר), שינויי דיירים TAMAR 2024 ותכנית מגרש 823-3. עדיין חסרים: היתר + טבלת שטחים, חוזה, תצ"ר, שרטוטי חצר | V7: =IF(AND($A7<>"",F7<>"הושלם",F7<>"בוטל",J7<>""),IF(J7<=Today_+14,IF(K7="",99999,K7)+ROW()/100000,""),"") | W7: =IFERROR(IF($A7="","",CHOOSE(MATCH(G7,{"לא התחיל","בתהליך","ממתין","תקוע","באיחור","הושלם","בוטל"},0),1,2,3,3,4,5,6)*100000+IF(K7="",99999,K7)+ROW()/1000000),"") | X7: =IF(AND($A7<>"",F7<>"הושלם",F7<>"בוטל",OR(ISNUMBER(SEARCH("אריאל",D7)),D7="כל המשפחה")),IF(K7="",99999,K7)+ROW()/100000,"") | Y7: =IF(AND($A7<>"",F7<>"הושלם",F7<>"בוטל",OR(ISNUMBER(SEARCH("רינת",D7)),D7="כל המשפחה")),IF(K7="",99999,K7)+ROW()/100000,"") | Z7: =IF(AND($A7<>"",F7<>"הושלם",F7<>"בוטל",OR(ISNUMBER(SEARCH("תמר",D7)))),IF(K7="",99999,K7)+ROW()/100000,"") | AA7: =IF(AND($A7<>"",F7<>"הושלם",F7<>"בוטל",NOT(ISNUMBER(SEARCH("אריאל",D7))),NOT(ISNUMBER(SEARCH("רינת",D7))),NOT(ISNUMBER(SEARCH("תמר",D7))),D7<>"כל המשפחה"),IF(K7="",99999,K7)+ROW()/100000,"")
A8: T-004 | B8: 0 איסוף מידע | C8: תיאום מועד מסירת מפתח | D8: אריאל | E8: גבוהה | F8: לא התחיל | G8: =IF($A8="","",IF(AND(F8<>"הושלם",F8<>"בוטל",K8<>"",K8<Today_),"באיחור",IF(F8="","לא התחיל",F8))) | I8: =IF($A8="","",IF(H8<>"",H8,IF(F8="הושלם",1,IF(F8="בתהליך",0.5,IF(OR(F8="ממתין",F8="תקוע"),0.25,0))))) | J8: =IF(OR($A8="",O8=""),"",IF(AND(N8="K",KeyActual<>""),O8+(KeyActual-KeyA),IF(Scenario="B",IF(Q8="",O8,Q8),O8))) | K8: =IF(OR($A8="",P8=""),"",IF(AND(N8="K",KeyActual<>""),P8+(KeyActual-KeyA),IF(Scenario="B",IF(R8="",P8,R8),P8))) | L8: =IF(OR($A8="",K8=""),"",IF(OR(F8="הושלם",F8="בוטל"),"",K8-Today_)) | M8: — | N8: F | O8: 46313 | P8: 46325 | Q8: 46313 | R8: 46325 | S8: לברר מול המוכר/יזם מועד מסירה מדויק (טווח 1.12–5.1) ותנאי גישה לפני מסירה (מדידות/הצעות מחיר) | T8: חוזה רכישה, איש קשר מוכר | U8: מועד המפתח = עוגן לכל התוכנית | 11.10: במסמכי Drive אין תאריך מסירה (מפרט המכר הוא נוסח לדוגמה למגרש 822, לא חתום) | 11.10(2): הקובץ המצורף החדש = כפילות של תכנית אינסטלציה; עדיין אין תאריך מסירה במסמכים | V8: =IF(AND($A8<>"",F8<>"הושלם",F8<>"בוטל",J8<>""),IF(J8<=Today_+14,IF(K8="",99999,K8)+ROW()/100000,""),"") | W8: =IFERROR(IF($A8="","",CHOOSE(MATCH(G8,{"לא התחיל","בתהליך","ממתין","תקוע","באיחור","הושלם","בוטל"},0),1,2,3,3,4,5,6)*100000+IF(K8="",99999,K8)+ROW()/1000000),"") | X8: =IF(AND($A8<>"",F8<>"הושלם",F8<>"בוטל",OR(ISNUMBER(SEARCH("אריאל",D8)),D8="כל המשפחה")),IF(K8="",99999,K8)+ROW()/100000,"") | Y8: =IF(AND($A8<>"",F8<>"הושלם",F8<>"בוטל",OR(ISNUMBER(SEARCH("רינת",D8)),D8="כל המשפחה")),IF(K8="",99999,K8)+ROW()/100000,"") | Z8: =IF(AND($A8<>"",F8<>"הושלם",F8<>"בוטל",OR(ISNUMBER(SEARCH("תמר",D8)))),IF(K8="",99999,K8)+ROW()/100000,"") | AA8: =IF(AND($A8<>"",F8<>"הושלם",F8<>"בוטל",NOT(ISNUMBER(SEARCH("אריאל",D8))),NOT(ISNUMBER(SEARCH("רינת",D8))),NOT(ISNUMBER(SEARCH("תמר",D8))),D8<>"כל המשפחה"),IF(K8="",99999,K8)+ROW()/100000,"")
A9: T-005 | B9: 0 איסוף מידע | C9: מדידות משלימות | D9: אריאל/רינת | E9: בינונית | F9: לא התחיל | G9: =IF($A9="","",IF(AND(F9<>"הושלם",F9<>"בוטל",K9<>"",K9<Today_),"באיחור",IF(F9="","לא התחיל",F9))) | I9: =IF($A9="","",IF(H9<>"",H9,IF(F9="הושלם",1,IF(F9="בתהליך",0.5,IF(OR(F9="ממתין",F9="תקוע"),0.25,0))))) | J9: =IF(OR($A9="",O9=""),"",IF(AND(N9="K",KeyActual<>""),O9+(KeyActual-KeyA),IF(Scenario="B",IF(Q9="",O9,Q9),O9))) | K9: =IF(OR($A9="",P9=""),"",IF(AND(N9="K",KeyActual<>""),P9+(KeyActual-KeyA),IF(Scenario="B",IF(R9="",P9,R9),P9))) | L9: =IF(OR($A9="",K9=""),"",IF(OR(F9="הושלם",F9="בוטל"),"",K9-Today_)) | M9: T-004 | N9: F | O9: 46318 | P9: 46341 | Q9: 46318 | R9: 46341 | S9: אורך פינת אוכל, חדר אורחים, מזווה, חדרי ילדים, מקום מקרר ראשי, חדרים למזגנים | T9: מטר לייזר, תוכניות; לציין מקור לכל מידה | U9: תלוי בגישה לבית לפני מסירה | V9: =IF(AND($A9<>"",F9<>"הושלם",F9<>"בוטל",J9<>""),IF(J9<=Today_+14,IF(K9="",99999,K9)+ROW()/100000,""),"") | W9: =IFERROR(IF($A9="","",CHOOSE(MATCH(G9,{"לא התחיל","בתהליך","ממתין","תקוע","באיחור","הושלם","בוטל"},0),1,2,3,3,4,5,6)*100000+IF(K9="",99999,K9)+ROW()/1000000),"") | X9: =IF(AND($A9<>"",F9<>"הושלם",F9<>"בוטל",OR(ISNUMBER(SEARCH("אריאל",D9)),D9="כל המשפחה")),IF(K9="",99999,K9)+ROW()/100000,"") | Y9: =IF(AND($A9<>"",F9<>"הושלם",F9<>"בוטל",OR(ISNUMBER(SEARCH("רינת",D9)),D9="כל המשפחה")),IF(K9="",99999,K9)+ROW()/100000,"") | Z9: =IF(AND($A9<>"",F9<>"הושלם",F9<>"בוטל",OR(ISNUMBER(SEARCH("תמר",D9)))),IF(K9="",99999,K9)+ROW()/100000,"") | AA9: =IF(AND($A9<>"",F9<>"הושלם",F9<>"בוטל",NOT(ISNUMBER(SEARCH("אריאל",D9))),NOT(ISNUMBER(SEARCH("רינת",D9))),NOT(ISNUMBER(SEARCH("תמר",D9))),D9<>"כל המשפחה"),IF(K9="",99999,K9)+ROW()/100000,"")
A10: T-010 | B10: 1 היתכנות | C10: בחירת אנשי מקצוע: אדריכל רישוי / מהנדס / מודד | D10: אריאל | E10: גבוהה | F10: לא התחיל | G10: =IF($A10="","",IF(AND(F10<>"הושלם",F10<>"בוטל",K10<>"",K10<Today_),"באיחור",IF(F10="","לא התחיל",F10))) | I10: =IF($A10="","",IF(H10<>"",H10,IF(F10="הושלם",1,IF(F10="בתהליך",0.5,IF(OR(F10="ממתין",F10="תקוע"),0.25,0))))) | J10: =IF(OR($A10="",O10=""),"",IF(AND(N10="K",KeyActual<>""),O10+(KeyActual-KeyA),IF(Scenario="B",IF(Q10="",O10,Q10),O10))) | K10: =IF(OR($A10="",P10=""),"",IF(AND(N10="K",KeyActual<>""),P10+(KeyActual-KeyA),IF(Scenario="B",IF(R10="",P10,R10),P10))) | L10: =IF(OR($A10="",K10=""),"",IF(OR(F10="הושלם",F10="בוטל"),"",K10-Today_)) | M10: T-001 | N10: F | O10: 46318 | P10: 46334 | Q10: 46318 | R10: 46334 | S10: 3 הצעות לכל אחד; החלטה #3 | T10: תיאור היקף, תוכניות, תב"ע 7001686 | U10: לא לפנות לספק ללא אישור אריאל | V10: =IF(AND($A10<>"",F10<>"הושלם",F10<>"בוטל",J10<>""),IF(J10<=Today_+14,IF(K10="",99999,K10)+ROW()/100000,""),"") | W10: =IFERROR(IF($A10="","",CHOOSE(MATCH(G10,{"לא התחיל","בתהליך","ממתין","תקוע","באיחור","הושלם","בוטל"},0),1,2,3,3,4,5,6)*100000+IF(K10="",99999,K10)+ROW()/1000000),"") | X10: =IF(AND($A10<>"",F10<>"הושלם",F10<>"בוטל",OR(ISNUMBER(SEARCH("אריאל",D10)),D10="כל המשפחה")),IF(K10="",99999,K10)+ROW()/100000,"") | Y10: =IF(AND($A10<>"",F10<>"הושלם",F10<>"בוטל",OR(ISNUMBER(SEARCH("רינת",D10)),D10="כל המשפחה")),IF(K10="",99999,K10)+ROW()/100000,"") | Z10: =IF(AND($A10<>"",F10<>"הושלם",F10<>"בוטל",OR(ISNUMBER(SEARCH("תמר",D10)))),IF(K10="",99999,K10)+ROW()/100000,"") | AA10: =IF(AND($A10<>"",F10<>"הושלם",F10<>"בוטל",NOT(ISNUMBER(SEARCH("אריאל",D10))),NOT(ISNUMBER(SEARCH("רינת",D10))),NOT(ISNUMBER(SEARCH("תמר",D10))),D10<>"כל המשפחה"),IF(K10="",99999,K10)+ROW()/100000,"")
A11: T-011 | B11: 1 היתכנות | C11: מודד: מפת מדידה + גבולות 823/3 | D11: מודד | E11: גבוהה | F11: לא התחיל | G11: =IF($A11="","",IF(AND(F11<>"הושלם",F11<>"בוטל",K11<>"",K11<Today_),"באיחור",IF(F11="","לא התחיל",F11))) | I11: =IF($A11="","",IF(H11<>"",H11,IF(F11="הושלם",1,IF(F11="בתהליך",0.5,IF(OR(F11="ממתין",F11="תקוע"),0.25,0))))) | J11: =IF(OR($A11="",O11=""),"",IF(AND(N11="K",KeyActual<>""),O11+(KeyActual-KeyA),IF(Scenario="B",IF(Q11="",O11,Q11),O11))) | K11: =IF(OR($A11="",P11=""),"",IF(AND(N11="K",KeyActual<>""),P11+(KeyActual-KeyA),IF(Scenario="B",IF(R11="",P11,R11),P11))) | L11: =IF(OR($A11="",K11=""),"",IF(OR(F11="הושלם",F11="בוטל"),"",K11-Today_)) | M11: T-010 | N11: F | O11: 46334 | P11: 46356 | Q11: 46334 | R11: 46356 | S11: מפת מדידה עדכנית 1:250 (נדרשת להיתר לפי ה'2); החלטה #4 | T11: נסח/תצ"ר, תכנית חלוקה 823/1-3 | U11: פותר את סתירת 528 מ"ר / 0.5 דונם | V11: =IF(AND($A11<>"",F11<>"הושלם",F11<>"בוטל",J11<>""),IF(J11<=Today_+14,IF(K11="",99999,K11)+ROW()/100000,""),"") | W11: =IFERROR(IF($A11="","",CHOOSE(MATCH(G11,{"לא התחיל","בתהליך","ממתין","תקוע","באיחור","הושלם","בוטל"},0),1,2,3,3,4,5,6)*100000+IF(K11="",99999,K11)+ROW()/1000000),"") | X11: =IF(AND($A11<>"",F11<>"הושלם",F11<>"בוטל",OR(ISNUMBER(SEARCH("אריאל",D11)),D11="כל המשפחה")),IF(K11="",99999,K11)+ROW()/100000,"") | Y11: =IF(AND($A11<>"",F11<>"הושלם",F11<>"בוטל",OR(ISNUMBER(SEARCH("רינת",D11)),D11="כל המשפחה")),IF(K11="",99999,K11)+ROW()/100000,"") | Z11: =IF(AND($A11<>"",F11<>"הושלם",F11<>"בוטל",OR(ISNUMBER(SEARCH("תמר",D11)))),IF(K11="",99999,K11)+ROW()/100000,"") | AA11: =IF(AND($A11<>"",F11<>"הושלם",F11<>"בוטל",NOT(ISNUMBER(SEARCH("אריאל",D11))),NOT(ISNUMBER(SEARCH("רינת",D11))),NOT(ISNUMBER(SEARCH("תמר",D11))),D11<>"כל המשפחה"),IF(K11="",99999,K11)+ROW()/100000,"")
A12: T-012 | B12: 1 היתכנות | C12: בירור בוועדה (מטה בנימין): זכויות 823/3, קליניקה, מחסן, מרפסת | D12: אדריכל/אריאל | E12: גבוהה | F12: לא התחיל | G12: =IF($A12="","",IF(AND(F12<>"הושלם",F12<>"בוטל",K12<>"",K12<Today_),"באיחור",IF(F12="","לא התחיל",F12))) | I12: =IF($A12="","",IF(H12<>"",H12,IF(F12="הושלם",1,IF(F12="בתהליך",0.5,IF(OR(F12="ממתין",F12="תקוע"),0.25,0))))) | J12: =IF(OR($A12="",O12=""),"",IF(AND(N12="K",KeyActual<>""),O12+(KeyActual-KeyA),IF(Scenario="B",IF(Q12="",O12,Q12),O12))) | K12: =IF(OR($A12="",P12=""),"",IF(AND(N12="K",KeyActual<>""),P12+(KeyActual-KeyA),IF(Scenario="B",IF(R12="",P12,R12),P12))) | L12: =IF(OR($A12="",K12=""),"",IF(OR(F12="הושלם",F12="בוטל"),"",K12-Today_)) | M12: T-010 | N12: F | O12: 46327 | P12: 46356 | Q12: 46327 | R12: 46356 | S12: שאלות: חלוקת 6 יח"ד, קו בניין 3 מ', קליניקה (תב"ע: מגורים בלבד), סגירת פרגולה אסורה (4.6ז), גדר עד 1.5 מ'; החלטה #5 | T12: zoning_taba_7001686.md, היתר קיים, תכנית בינוי; היתר 823/3 + טבלת שטחים (דגם "200 מ"ר" מול 190 עיקרי) | U12: ממצאי התב"ע — קריאה חזותית, לאמת | 11.10(2): הורביץ בצפון → גבול צד, קו בניין 3 מ'. ראו permit_classification.md | V12: =IF(AND($A12<>"",F12<>"הושלם",F12<>"בוטל",J12<>""),IF(J12<=Today_+14,IF(K12="",99999,K12)+ROW()/100000,""),"") | W12: =IFERROR(IF($A12="","",CHOOSE(MATCH(G12,{"לא התחיל","בתהליך","ממתין","תקוע","באיחור","הושלם","בוטל"},0),1,2,3,3,4,5,6)*100000+IF(K12="",99999,K12)+ROW()/1000000),"") | X12: =IF(AND($A12<>"",F12<>"הושלם",F12<>"בוטל",OR(ISNUMBER(SEARCH("אריאל",D12)),D12="כל המשפחה")),IF(K12="",99999,K12)+ROW()/100000,"") | Y12: =IF(AND($A12<>"",F12<>"הושלם",F12<>"בוטל",OR(ISNUMBER(SEARCH("רינת",D12)),D12="כל המשפחה")),IF(K12="",99999,K12)+ROW()/100000,"") | Z12: =IF(AND($A12<>"",F12<>"הושלם",F12<>"בוטל",OR(ISNUMBER(SEARCH("תמר",D12)))),IF(K12="",99999,K12)+ROW()/100000,"") | AA12: =IF(AND($A12<>"",F12<>"הושלם",F12<>"בוטל",NOT(ISNUMBER(SEARCH("אריאל",D12))),NOT(ISNUMBER(SEARCH("רינת",D12))),NOT(ISNUMBER(SEARCH("תמר",D12))),D12<>"כל המשפחה"),IF(K12="",99999,K12)+ROW()/100000,"")
A13: T-013 | B13: 1 היתכנות | C13: מהנדס: אילו חלונות בסלון אפשר להרחיב | D13: מהנדס | E13: גבוהה | F13: לא התחיל | G13: =IF($A13="","",IF(AND(F13<>"הושלם",F13<>"בוטל",K13<>"",K13<Today_),"באיחור",IF(F13="","לא התחיל",F13))) | I13: =IF($A13="","",IF(H13<>"",H13,IF(F13="הושלם",1,IF(F13="בתהליך",0.5,IF(OR(F13="ממתין",F13="תקוע"),0.25,0))))) | J13: =IF(OR($A13="",O13=""),"",IF(AND(N13="K",KeyActual<>""),O13+(KeyActual-KeyA),IF(Scenario="B",IF(Q13="",O13,Q13),O13))) | K13: =IF(OR($A13="",P13=""),"",IF(AND(N13="K",KeyActual<>""),P13+(KeyActual-KeyA),IF(Scenario="B",IF(R13="",P13,R13),P13))) | L13: =IF(OR($A13="",K13=""),"",IF(OR(F13="הושלם",F13="בוטל"),"",K13-Today_)) | M13: T-003,T-010 | N13: F | O13: 46334 | P13: 46356 | Q13: 46334 | R13: 46356 | S13: בדיקת קירות/עמודים/קורות מול תוכניות; החלטה #6 | T13: תוכניות קונסטרוקציה; מידות 405/424 ס"מ | U13: חובה לפני הזמנת אלומיניום | 11.10: יש תוכניות קונסטרוקציה של הדגם (חננאל כפיר, 16/04/2023) בתיקייה source/drive/kablan | V13: =IF(AND($A13<>"",F13<>"הושלם",F13<>"בוטל",J13<>""),IF(J13<=Today_+14,IF(K13="",99999,K13)+ROW()/100000,""),"") | W13: =IFERROR(IF($A13="","",CHOOSE(MATCH(G13,{"לא התחיל","בתהליך","ממתין","תקוע","באיחור","הושלם","בוטל"},0),1,2,3,3,4,5,6)*100000+IF(K13="",99999,K13)+ROW()/1000000),"") | X13: =IF(AND($A13<>"",F13<>"הושלם",F13<>"בוטל",OR(ISNUMBER(SEARCH("אריאל",D13)),D13="כל המשפחה")),IF(K13="",99999,K13)+ROW()/100000,"") | Y13: =IF(AND($A13<>"",F13<>"הושלם",F13<>"בוטל",OR(ISNUMBER(SEARCH("רינת",D13)),D13="כל המשפחה")),IF(K13="",99999,K13)+ROW()/100000,"") | Z13: =IF(AND($A13<>"",F13<>"הושלם",F13<>"בוטל",OR(ISNUMBER(SEARCH("תמר",D13)))),IF(K13="",99999,K13)+ROW()/100000,"") | AA13: =IF(AND($A13<>"",F13<>"הושלם",F13<>"בוטל",NOT(ISNUMBER(SEARCH("אריאל",D13))),NOT(ISNUMBER(SEARCH("רינת",D13))),NOT(ISNUMBER(SEARCH("תמר",D13))),D13<>"כל המשפחה"),IF(K13="",99999,K13)+ROW()/100000,"")
A14: T-014 | B14: 1 היתכנות | C14: סקר תשתיות (חשמל/אינסטלציה/ניקוז) | D14: קבלן/חשמלאי | E14: בינונית | F14: לא התחיל | G14: =IF($A14="","",IF(AND(F14<>"הושלם",F14<>"בוטל",K14<>"",K14<Today_),"באיחור",IF(F14="","לא התחיל",F14))) | I14: =IF($A14="","",IF(H14<>"",H14,IF(F14="הושלם",1,IF(F14="בתהליך",0.5,IF(OR(F14="ממתין",F14="תקוע"),0.25,0))))) | J14: =IF(OR($A14="",O14=""),"",IF(AND(N14="K",KeyActual<>""),O14+(KeyActual-KeyA),IF(Scenario="B",IF(Q14="",O14,Q14),O14))) | K14: =IF(OR($A14="",P14=""),"",IF(AND(N14="K",KeyActual<>""),P14+(KeyActual-KeyA),IF(Scenario="B",IF(R14="",P14,R14),P14))) | L14: =IF(OR($A14="",K14=""),"",IF(OR(F14="הושלם",F14="בוטל"),"",K14-Today_)) | M14: T-004 | N14: F | O14: 46341 | P14: 46371 | Q14: 46341 | R14: 46371 | S14: חשמלאי+אינסטלטור: מצב לוח, הספק, ביוב, ניקוז מרפסת | T14: גישה לבית | U14: יכול לגלוש אחרי מפתח | V14: =IF(AND($A14<>"",F14<>"הושלם",F14<>"בוטל",J14<>""),IF(J14<=Today_+14,IF(K14="",99999,K14)+ROW()/100000,""),"") | W14: =IFERROR(IF($A14="","",CHOOSE(MATCH(G14,{"לא התחיל","בתהליך","ממתין","תקוע","באיחור","הושלם","בוטל"},0),1,2,3,3,4,5,6)*100000+IF(K14="",99999,K14)+ROW()/1000000),"") | X14: =IF(AND($A14<>"",F14<>"הושלם",F14<>"בוטל",OR(ISNUMBER(SEARCH("אריאל",D14)),D14="כל המשפחה")),IF(K14="",99999,K14)+ROW()/100000,"") | Y14: =IF(AND($A14<>"",F14<>"הושלם",F14<>"בוטל",OR(ISNUMBER(SEARCH("רינת",D14)),D14="כל המשפחה")),IF(K14="",99999,K14)+ROW()/100000,"") | Z14: =IF(AND($A14<>"",F14<>"הושלם",F14<>"בוטל",OR(ISNUMBER(SEARCH("תמר",D14)))),IF(K14="",99999,K14)+ROW()/100000,"") | AA14: =IF(AND($A14<>"",F14<>"הושלם",F14<>"בוטל",NOT(ISNUMBER(SEARCH("אריאל",D14))),NOT(ISNUMBER(SEARCH("רינת",D14))),NOT(ISNUMBER(SEARCH("תמר",D14))),D14<>"כל המשפחה"),IF(K14="",99999,K14)+ROW()/100000,"")
A15: T-020 | B15: 2 תכנון | C15: החלטה: היקף סגירת מרפסת הורים | D15: אריאל+רינת | E15: גבוהה | F15: לא התחיל | G15: =IF($A15="","",IF(AND(F15<>"הושלם",F15<>"בוטל",K15<>"",K15<Today_),"באיחור",IF(F15="","לא התחיל",F15))) | I15: =IF($A15="","",IF(H15<>"",H15,IF(F15="הושלם",1,IF(F15="בתהליך",0.5,IF(OR(F15="ממתין",F15="תקוע"),0.25,0))))) | J15: =IF(OR($A15="",O15=""),"",IF(AND(N15="K",KeyActual<>""),O15+(KeyActual-KeyA),IF(Scenario="B",IF(Q15="",O15,Q15),O15))) | K15: =IF(OR($A15="",P15=""),"",IF(AND(N15="K",KeyActual<>""),P15+(KeyActual-KeyA),IF(Scenario="B",IF(R15="",P15,R15),P15))) | L15: =IF(OR($A15="",K15=""),"",IF(OR(F15="הושלם",F15="בוטל"),"",K15-Today_)) | M15: T-012 | N15: F | O15: 46346 | P15: 46366 | Q15: 46346 | R15: 46366 | S15: 830×259; שימוש: חדר ארונות/מיני-סלון/עבודה; החלטה #7 | T15: תשובת ועדה, מהנדס | U15: ייתכן שאסור/דורש היתר | V15: =IF(AND($A15<>"",F15<>"הושלם",F15<>"בוטל",J15<>""),IF(J15<=Today_+14,IF(K15="",99999,K15)+ROW()/100000,""),"") | W15: =IFERROR(IF($A15="","",CHOOSE(MATCH(G15,{"לא התחיל","בתהליך","ממתין","תקוע","באיחור","הושלם","בוטל"},0),1,2,3,3,4,5,6)*100000+IF(K15="",99999,K15)+ROW()/1000000),"") | X15: =IF(AND($A15<>"",F15<>"הושלם",F15<>"בוטל",OR(ISNUMBER(SEARCH("אריאל",D15)),D15="כל המשפחה")),IF(K15="",99999,K15)+ROW()/100000,"") | Y15: =IF(AND($A15<>"",F15<>"הושלם",F15<>"בוטל",OR(ISNUMBER(SEARCH("רינת",D15)),D15="כל המשפחה")),IF(K15="",99999,K15)+ROW()/100000,"") | Z15: =IF(AND($A15<>"",F15<>"הושלם",F15<>"בוטל",OR(ISNUMBER(SEARCH("תמר",D15)))),IF(K15="",99999,K15)+ROW()/100000,"") | AA15: =IF(AND($A15<>"",F15<>"הושלם",F15<>"בוטל",NOT(ISNUMBER(SEARCH("אריאל",D15))),NOT(ISNUMBER(SEARCH("רינת",D15))),NOT(ISNUMBER(SEARCH("תמר",D15))),D15<>"כל המשפחה"),IF(K15="",99999,K15)+ROW()/100000,"")
A16: T-021 | B16: 2 תכנון | C16: קליניקה + מחסן: החלטה על חלופה | D16: אריאל+אדריכל | E16: גבוהה | F16: לא התחיל | G16: =IF($A16="","",IF(AND(F16<>"הושלם",F16<>"בוטל",K16<>"",K16<Today_),"באיחור",IF(F16="","לא התחיל",F16))) | I16: =IF($A16="","",IF(H16<>"",H16,IF(F16="הושלם",1,IF(F16="בתהליך",0.5,IF(OR(F16="ממתין",F16="תקוע"),0.25,0))))) | J16: =IF(OR($A16="",O16=""),"",IF(AND(N16="K",KeyActual<>""),O16+(KeyActual-KeyA),IF(Scenario="B",IF(Q16="",O16,Q16),O16))) | K16: =IF(OR($A16="",P16=""),"",IF(AND(N16="K",KeyActual<>""),P16+(KeyActual-KeyA),IF(Scenario="B",IF(R16="",P16,R16),P16))) | L16: =IF(OR($A16="",K16=""),"",IF(OR(F16="הושלם",F16="בוטל"),"",K16-Today_)) | M16: T-011,T-012 | N16: F | O16: 46351 | P16: 46376 | Q16: 46351 | R16: 46376 | S16: לאור התב"ע (מגורים בלבד, מחסן אינטגרלי ≤15 מ"ר, קו 3 מ'); החלטה #8 | T16: מפת מדידה, תשובת ועדה | U16: סיכון אדום | 11.10(2): הגבול הצפוני (הורביץ) = קו בניין 3 מ'; סיווג היתר: נדרש/כנראה לא ניתן לאשר | V16: =IF(AND($A16<>"",F16<>"הושלם",F16<>"בוטל",J16<>""),IF(J16<=Today_+14,IF(K16="",99999,K16)+ROW()/100000,""),"") | W16: =IFERROR(IF($A16="","",CHOOSE(MATCH(G16,{"לא התחיל","בתהליך","ממתין","תקוע","באיחור","הושלם","בוטל"},0),1,2,3,3,4,5,6)*100000+IF(K16="",99999,K16)+ROW()/1000000),"") | X16: =IF(AND($A16<>"",F16<>"הושלם",F16<>"בוטל",OR(ISNUMBER(SEARCH("אריאל",D16)),D16="כל המשפחה")),IF(K16="",99999,K16)+ROW()/100000,"") | Y16: =IF(AND($A16<>"",F16<>"הושלם",F16<>"בוטל",OR(ISNUMBER(SEARCH("רינת",D16)),D16="כל המשפחה")),IF(K16="",99999,K16)+ROW()/100000,"") | Z16: =IF(AND($A16<>"",F16<>"הושלם",F16<>"בוטל",OR(ISNUMBER(SEARCH("תמר",D16)))),IF(K16="",99999,K16)+ROW()/100000,"") | AA16: =IF(AND($A16<>"",F16<>"הושלם",F16<>"בוטל",NOT(ISNUMBER(SEARCH("אריאל",D16))),NOT(ISNUMBER(SEARCH("רינת",D16))),NOT(ISNUMBER(SEARCH("תמר",D16))),D16<>"כל המשפחה"),IF(K16="",99999,K16)+ROW()/100000,"")
A17: T-022 | B17: 2 תכנון | C17: היקף מטבח + מזווה | D17: אריאל+רינת | E17: גבוהה | F17: לא התחיל | G17: =IF($A17="","",IF(AND(F17<>"הושלם",F17<>"בוטל",K17<>"",K17<Today_),"באיחור",IF(F17="","לא התחיל",F17))) | I17: =IF($A17="","",IF(H17<>"",H17,IF(F17="הושלם",1,IF(F17="בתהליך",0.5,IF(OR(F17="ממתין",F17="תקוע"),0.25,0))))) | J17: =IF(OR($A17="",O17=""),"",IF(AND(N17="K",KeyActual<>""),O17+(KeyActual-KeyA),IF(Scenario="B",IF(Q17="",O17,Q17),O17))) | K17: =IF(OR($A17="",P17=""),"",IF(AND(N17="K",KeyActual<>""),P17+(KeyActual-KeyA),IF(Scenario="B",IF(R17="",P17,R17),P17))) | L17: =IF(OR($A17="",K17=""),"",IF(OR(F17="הושלם",F17="בוטל"),"",K17-Today_)) | M17: T-001 | N17: F | O17: 46327 | P17: 46348 | Q17: 46327 | R17: 46348 | S17: מלא/אי/מכשירים; מקרר נוסף במזווה; החלטה #9 | T17: מידות 319/470, רשימת מכשירים | U17: נדרש לפני נקודות חשמל-מים | V17: =IF(AND($A17<>"",F17<>"הושלם",F17<>"בוטל",J17<>""),IF(J17<=Today_+14,IF(K17="",99999,K17)+ROW()/100000,""),"") | W17: =IFERROR(IF($A17="","",CHOOSE(MATCH(G17,{"לא התחיל","בתהליך","ממתין","תקוע","באיחור","הושלם","בוטל"},0),1,2,3,3,4,5,6)*100000+IF(K17="",99999,K17)+ROW()/1000000),"") | X17: =IF(AND($A17<>"",F17<>"הושלם",F17<>"בוטל",OR(ISNUMBER(SEARCH("אריאל",D17)),D17="כל המשפחה")),IF(K17="",99999,K17)+ROW()/100000,"") | Y17: =IF(AND($A17<>"",F17<>"הושלם",F17<>"בוטל",OR(ISNUMBER(SEARCH("רינת",D17)),D17="כל המשפחה")),IF(K17="",99999,K17)+ROW()/100000,"") | Z17: =IF(AND($A17<>"",F17<>"הושלם",F17<>"בוטל",OR(ISNUMBER(SEARCH("תמר",D17)))),IF(K17="",99999,K17)+ROW()/100000,"") | AA17: =IF(AND($A17<>"",F17<>"הושלם",F17<>"בוטל",NOT(ISNUMBER(SEARCH("אריאל",D17))),NOT(ISNUMBER(SEARCH("רינת",D17))),NOT(ISNUMBER(SEARCH("תמר",D17))),D17<>"כל המשפחה"),IF(K17="",99999,K17)+ROW()/100000,"")
A18: T-023 | B18: 2 תכנון | C18: קונספט חוץ | D18: אריאל+רינת | E18: נמוכה | F18: לא התחיל | G18: =IF($A18="","",IF(AND(F18<>"הושלם",F18<>"בוטל",K18<>"",K18<Today_),"באיחור",IF(F18="","לא התחיל",F18))) | I18: =IF($A18="","",IF(H18<>"",H18,IF(F18="הושלם",1,IF(F18="בתהליך",0.5,IF(OR(F18="ממתין",F18="תקוע"),0.25,0))))) | J18: =IF(OR($A18="",O18=""),"",IF(AND(N18="K",KeyActual<>""),O18+(KeyActual-KeyA),IF(Scenario="B",IF(Q18="",O18,Q18),O18))) | K18: =IF(OR($A18="",P18=""),"",IF(AND(N18="K",KeyActual<>""),P18+(KeyActual-KeyA),IF(Scenario="B",IF(R18="",P18,R18),P18))) | L18: =IF(OR($A18="",K18=""),"",IF(OR(F18="הושלם",F18="בוטל"),"",K18-Today_)) | M18: T-011,T-012 | N18: F | O18: 46357 | P18: 46402 | Q18: 46357 | R18: 46402 | S18: מטבח חוץ, הצללה (פרגולה לא נסגרת), גידור (זכוכית? לבדוק), גינה; החלטה #10 | T18: תקציב גינה 20–50 אלף (לא אומת) | U18: יכול לרוץ אחרי כניסה | V18: =IF(AND($A18<>"",F18<>"הושלם",F18<>"בוטל",J18<>""),IF(J18<=Today_+14,IF(K18="",99999,K18)+ROW()/100000,""),"") | W18: =IFERROR(IF($A18="","",CHOOSE(MATCH(G18,{"לא התחיל","בתהליך","ממתין","תקוע","באיחור","הושלם","בוטל"},0),1,2,3,3,4,5,6)*100000+IF(K18="",99999,K18)+ROW()/1000000),"") | X18: =IF(AND($A18<>"",F18<>"הושלם",F18<>"בוטל",OR(ISNUMBER(SEARCH("אריאל",D18)),D18="כל המשפחה")),IF(K18="",99999,K18)+ROW()/100000,"") | Y18: =IF(AND($A18<>"",F18<>"הושלם",F18<>"בוטל",OR(ISNUMBER(SEARCH("רינת",D18)),D18="כל המשפחה")),IF(K18="",99999,K18)+ROW()/100000,"") | Z18: =IF(AND($A18<>"",F18<>"הושלם",F18<>"בוטל",OR(ISNUMBER(SEARCH("תמר",D18)))),IF(K18="",99999,K18)+ROW()/100000,"") | AA18: =IF(AND($A18<>"",F18<>"הושלם",F18<>"בוטל",NOT(ISNUMBER(SEARCH("אריאל",D18))),NOT(ISNUMBER(SEARCH("רינת",D18))),NOT(ISNUMBER(SEARCH("תמר",D18))),D18<>"כל המשפחה"),IF(K18="",99999,K18)+ROW()/100000,"")
... A27: T-043 | B27: 5 מערכות | C27: מיזוג: התקנת הכנות (צנרת) בזמן עבודות | D27: מתקין מיזוג | E27: בינונית | F27: לא התחיל | G27: =IF($A27="","",IF(AND(F27<>"הושלם",F27<>"בוטל",K27<>"",K27<Today_),"באיחור",IF(F27="","לא התחיל",F27))) | I27: =IF($A27="","",IF(H27<>"",H27,IF(F27="הושלם",1,IF(F27="בתהליך",0.5,IF(OR(F27="ממתין",F27="תקוע"),0.25,0))))) | J27: =IF(OR($A27="",O27=""),"",IF(AND(N27="K",KeyActual<>""),O27+(KeyActual-KeyA),IF(Scenario="B",IF(Q27="",O27,Q27),O27))) | K27: =IF(OR($A27="",P27=""),"",IF(AND(N27="K",KeyActual<>""),P27+(KeyActual-KeyA),IF(Scenario="B",IF(R27="",P27,R27),P27))) | L27: =IF(OR($A27="",K27=""),"",IF(OR(F27="הושלם",F27="בוטל"),"",K27-Today_)) | M27: T-042,T-031 | N27: K | O27: 46371 | P27: 46392 | Q27: 46406 | R27: 46427 | S27: צנרת גז/ניקוז/חשמל לפני טיח/תקרה | T27: תוכנית תיאום מערכות | U27: חייב לפני גמר | V27: =IF(AND($A27<>"",F27<>"הושלם",F27<>"בוטל",J27<>""),IF(J27<=Today_+14,IF(K27="",99999,K27)+ROW()/100000,""),"") | W27: =IFERROR(IF($A27="","",CHOOSE(MATCH(G27,{"לא התחיל","בתהליך","ממתין","תקוע","באיחור","הושלם","בוטל"},0),1,2,3,3,4,5,6)*100000+IF(K27="",99999,K27)+ROW()/1000000),"") | X27: =IF(AND($A27<>"",F27<>"הושלם",F27<>"בוטל",OR(ISNUMBER(SEARCH("אריאל",D27)),D27="כל המשפחה")),IF(K27="",99999,K27)+ROW()/100000,"") | Y27: =IF(AND($A27<>"",F27<>"הושלם",F27<>"בוטל",OR(ISNUMBER(SEARCH("רינת",D27)),D27="כל המשפחה")),IF(K27="",99999,K27)+ROW()/100000,"") | Z27: =IF(AND($A27<>"",F27<>"הושלם",F27<>"בוטל",OR(ISNUMBER(SEARCH("תמר",D27)))),IF(K27="",99999,K27)+ROW()/100000,"") | AA27: =IF(AND($A27<>"",F27<>"הושלם",F27<>"בוטל",NOT(ISNUMBER(SEARCH("אריאל",D27))),NOT(ISNUMBER(SEARCH("רינת",D27))),NOT(ISNUMBER(SEARCH("תמר",D27))),D27<>"כל המשפחה"),IF(K27="",99999,K27)+ROW()/100000,"")
A28: T-044 | B28: 5 מערכות | C28: מיזוג: התקנת יחידות והפעלה | D28: מתקין מיזוג | E28: בינונית | F28: לא התחיל | G28: =IF($A28="","",IF(AND(F28<>"הושלם",F28<>"בוטל",K28<>"",K28<Today_),"באיחור",IF(F28="","לא התחיל",F28))) | I28: =IF($A28="","",IF(H28<>"",H28,IF(F28="הושלם",1,IF(F28="בתהליך",0.5,IF(OR(F28="ממתין",F28="תקוע"),0.25,0))))) | J28: =IF(OR($A28="",O28=""),"",IF(AND(N28="K",KeyActual<>""),O28+(KeyActual-KeyA),IF(Scenario="B",IF(Q28="",O28,Q28),O28))) | K28: =IF(OR($A28="",P28=""),"",IF(AND(N28="K",KeyActual<>""),P28+(KeyActual-KeyA),IF(Scenario="B",IF(R28="",P28,R28),P28))) | L28: =IF(OR($A28="",K28=""),"",IF(OR(F28="הושלם",F28="בוטל"),"",K28-Today_)) | M28: T-043 | N28: K | O28: 46413 | P28: 46427 | Q28: 46448 | R28: 46462 | S28: אחרי צבע/ניקיון גס | U28: הנחה: גמר ~8 שבועות אחרי מפתח | V28: =IF(AND($A28<>"",F28<>"הושלם",F28<>"בוטל",J28<>""),IF(J28<=Today_+14,IF(K28="",99999,K28)+ROW()/100000,""),"") | W28: =IFERROR(IF($A28="","",CHOOSE(MATCH(G28,{"לא התחיל","בתהליך","ממתין","תקוע","באיחור","הושלם","בוטל"},0),1,2,3,3,4,5,6)*100000+IF(K28="",99999,K28)+ROW()/1000000),"") | X28: =IF(AND($A28<>"",F28<>"הושלם",F28<>"בוטל",OR(ISNUMBER(SEARCH("אריאל",D28)),D28="כל המשפחה")),IF(K28="",99999,K28)+ROW()/100000,"") | Y28: =IF(AND($A28<>"",F28<>"הושלם",F28<>"בוטל",OR(ISNUMBER(SEARCH("רינת",D28)),D28="כל המשפחה")),IF(K28="",99999,K28)+ROW()/100000,"") | Z28: =IF(AND($A28<>"",F28<>"הושלם",F28<>"בוטל",OR(ISNUMBER(SEARCH("תמר",D28)))),IF(K28="",99999,K28)+ROW()/100000,"") | AA28: =IF(AND($A28<>"",F28<>"הושלם",F28<>"בוטל",NOT(ISNUMBER(SEARCH("אריאל",D28))),NOT(ISNUMBER(SEARCH("רינת",D28))),NOT(ISNUMBER(SEARCH("תמר",D28))),D28<>"כל המשפחה"),IF(K28="",99999,K28)+ROW()/100000,"")
A29: T-050 | B29: 4 שלד ופתחים | C29: בדיקת מסירה ופרוטוקול | D29: אריאל+רינת | E29: גבוהה | F29: לא התחיל | G29: =IF($A29="","",IF(AND(F29<>"הושלם",F29<>"בוטל",K29<>"",K29<Today_),"באיחור",IF(F29="","לא התחיל",F29))) | I29: =IF($A29="","",IF(H29<>"",H29,IF(F29="הושלם",1,IF(F29="בתהליך",0.5,IF(OR(F29="ממתין",F29="תקוע"),0.25,0))))) | J29: =IF(OR($A29="",O29=""),"",IF(AND(N29="K",KeyActual<>""),O29+(KeyActual-KeyA),IF(Scenario="B",IF(Q29="",O29,Q29),O29))) | K29: =IF(OR($A29="",P29=""),"",IF(AND(N29="K",KeyActual<>""),P29+(KeyActual-KeyA),IF(Scenario="B",IF(R29="",P29,R29),P29))) | L29: =IF(OR($A29="",K29=""),"",IF(OR(F29="הושלם",F29="בוטל"),"",K29-Today_)) | M29: T-004 | N29: K | O29: 46357 | P29: 46358 | Q29: 46392 | R29: 46393 | S29: בדק בית/מעבר על ליקויים, קריאת מונים, צילום מצב | T29: צ'קליסט, מצלמה | U29: יום המפתח | 11.10(2): השיפוץ אחרי מסירה (אושר ע"י אריאל) — פרוטוקול מסירה מפורט חיוני לשמירת האחריות | V29: =IF(AND($A29<>"",F29<>"הושלם",F29<>"בוטל",J29<>""),IF(J29<=Today_+14,IF(K29="",99999,K29)+ROW()/100000,""),"") | W29: =IFERROR(IF($A29="","",CHOOSE(MATCH(G29,{"לא התחיל","בתהליך","ממתין","תקוע","באיחור","הושלם","בוטל"},0),1,2,3,3,4,5,6)*100000+IF(K29="",99999,K29)+ROW()/1000000),"") | X29: =IF(AND($A29<>"",F29<>"הושלם",F29<>"בוטל",OR(ISNUMBER(SEARCH("אריאל",D29)),D29="כל המשפחה")),IF(K29="",99999,K29)+ROW()/100000,"") | Y29: =IF(AND($A29<>"",F29<>"הושלם",F29<>"בוטל",OR(ISNUMBER(SEARCH("רינת",D29)),D29="כל המשפחה")),IF(K29="",99999,K29)+ROW()/100000,"") | Z29: =IF(AND($A29<>"",F29<>"הושלם",F29<>"בוטל",OR(ISNUMBER(SEARCH("תמר",D29)))),IF(K29="",99999,K29)+ROW()/100000,"") | AA29: =IF(AND($A29<>"",F29<>"הושלם",F29<>"בוטל",NOT(ISNUMBER(SEARCH("אריאל",D29))),NOT(ISNUMBER(SEARCH("רינת",D29))),NOT(ISNUMBER(SEARCH("תמר",D29))),D29<>"כל המשפחה"),IF(K29="",99999,K29)+ROW()/100000,"")
A30: T-051 | B30: 4 שלד ופתחים | C30: הרחבת חלונות / פתחים | D30: קבלן | E30: בינונית | F30: לא התחיל | G30: =IF($A30="","",IF(AND(F30<>"הושלם",F30<>"בוטל",K30<>"",K30<Today_),"באיחור",IF(F30="","לא התחיל",F30))) | I30: =IF($A30="","",IF(H30<>"",H30,IF(F30="הושלם",1,IF(F30="בתהליך",0.5,IF(OR(F30="ממתין",F30="תקוע"),0.25,0))))) | J30: =IF(OR($A30="",O30=""),"",IF(AND(N30="K",KeyActual<>""),O30+(KeyActual-KeyA),IF(Scenario="B",IF(Q30="",O30,Q30),O30))) | K30: =IF(OR($A30="",P30=""),"",IF(AND(N30="K",KeyActual<>""),P30+(KeyActual-KeyA),IF(Scenario="B",IF(R30="",P30,R30),P30))) | L30: =IF(OR($A30="",K30=""),"",IF(OR(F30="הושלם",F30="בוטל"),"",K30-Today_)) | M30: T-013,T-031,T-033 | N30: K | O30: 46371 | P30: 46392 | Q30: 46406 | R30: 46427 | S30: רק לפי אישור מהנדס | T30: היתר אם נדרש | U30: לוח זמן — הנחה | V30: =IF(AND($A30<>"",F30<>"הושלם",F30<>"בוטל",J30<>""),IF(J30<=Today_+14,IF(K30="",99999,K30)+ROW()/100000,""),"") | W30: =IFERROR(IF($A30="","",CHOOSE(MATCH(G30,{"לא התחיל","בתהליך","ממתין","תקוע","באיחור","הושלם","בוטל"},0),1,2,3,3,4,5,6)*100000+IF(K30="",99999,K30)+ROW()/1000000),"") | X30: =IF(AND($A30<>"",F30<>"הושלם",F30<>"בוטל",OR(ISNUMBER(SEARCH("אריאל",D30)),D30="כל המשפחה")),IF(K30="",99999,K30)+ROW()/100000,"") | Y30: =IF(AND($A30<>"",F30<>"הושלם",F30<>"בוטל",OR(ISNUMBER(SEARCH("רינת",D30)),D30="כל המשפחה")),IF(K30="",99999,K30)+ROW()/100000,"") | Z30: =IF(AND($A30<>"",F30<>"הושלם",F30<>"בוטל",OR(ISNUMBER(SEARCH("תמר",D30)))),IF(K30="",99999,K30)+ROW()/100000,"") | AA30: =IF(AND($A30<>"",F30<>"הושלם",F30<>"בוטל",NOT(ISNUMBER(SEARCH("אריאל",D30))),NOT(ISNUMBER(SEARCH("רינת",D30))),NOT(ISNUMBER(SEARCH("תמר",D30))),D30<>"כל המשפחה"),IF(K30="",99999,K30)+ROW()/100000,"")
A31: T-052 | B31: 5 מערכות | C31: חשמל ואינסטלציה (כולל מטבח) | D31: קבלן | E31: בינונית | F31: לא התחיל | G31: =IF($A31="","",IF(AND(F31<>"הושלם",F31<>"בוטל",K31<>"",K31<Today_),"באיחור",IF(F31="","לא התחיל",F31))) | I31: =IF($A31="","",IF(H31<>"",H31,IF(F31="הושלם",1,IF(F31="בתהליך",0.5,IF(OR(F31="ממתין",F31="תקוע"),0.25,0))))) | J31: =IF(OR($A31="",O31=""),"",IF(AND(N31="K",KeyActual<>""),O31+(KeyActual-KeyA),IF(Scenario="B",IF(Q31="",O31,Q31),O31))) | K31: =IF(OR($A31="",P31=""),"",IF(AND(N31="K",KeyActual<>""),P31+(KeyActual-KeyA),IF(Scenario="B",IF(R31="",P31,R31),P31))) | L31: =IF(OR($A31="",K31=""),"",IF(OR(F31="הושלם",F31="בוטל"),"",K31-Today_)) | M31: T-022,T-031 | N31: K | O31: 46367 | P31: 46392 | Q31: 46402 | R31: 46427 | S31: לפי תכנון מטבח וגופי תאורה | T31: תוכנית נקודות | U31: הנחה | V31: =IF(AND($A31<>"",F31<>"הושלם",F31<>"בוטל",J31<>""),IF(J31<=Today_+14,IF(K31="",99999,K31)+ROW()/100000,""),"") | W31: =IFERROR(IF($A31="","",CHOOSE(MATCH(G31,{"לא התחיל","בתהליך","ממתין","תקוע","באיחור","הושלם","בוטל"},0),1,2,3,3,4,5,6)*100000+IF(K31="",99999,K31)+ROW()/1000000),"") | X31: =IF(AND($A31<>"",F31<>"הושלם",F31<>"בוטל",OR(ISNUMBER(SEARCH("אריאל",D31)),D31="כל המשפחה")),IF(K31="",99999,K31)+ROW()/100000,"") | Y31: =IF(AND($A31<>"",F31<>"הושלם",F31<>"בוטל",OR(ISNUMBER(SEARCH("רינת",D31)),D31="כל המשפחה")),IF(K31="",99999,K31)+ROW()/100000,"") | Z31: =IF(AND($A31<>"",F31<>"הושלם",F31<>"בוטל",OR(ISNUMBER(SEARCH("תמר",D31)))),IF(K31="",99999,K31)+ROW()/100000,"") | AA31: =IF(AND($A31<>"",F31<>"הושלם",F31<>"בוטל",NOT(ISNUMBER(SEARCH("אריאל",D31))),NOT(ISNUMBER(SEARCH("רינת",D31))),NOT(ISNUMBER(SEARCH("תמר",D31))),D31<>"כל המשפחה"),IF(K31="",99999,K31)+ROW()/100000,"")
A32: T-053 | B32: 6 גמר פנים | C32: ריצוף/טיח/צבע/תאורה | D32: קבלן | E32: בינונית | F32: לא התחיל | G32: =IF($A32="","",IF(AND(F32<>"הושלם",F32<>"בוטל",K32<>"",K32<Today_),"באיחור",IF(F32="","לא התחיל",F32))) | I32: =IF($A32="","",IF(H32<>"",H32,IF(F32="הושלם",1,IF(F32="בתהליך",0.5,IF(OR(F32="ממתין",F32="תקוע"),0.25,0))))) | J32: =IF(OR($A32="",O32=""),"",IF(AND(N32="K",KeyActual<>""),O32+(KeyActual-KeyA),IF(Scenario="B",IF(Q32="",O32,Q32),O32))) | K32: =IF(OR($A32="",P32=""),"",IF(AND(N32="K",KeyActual<>""),P32+(KeyActual-KeyA),IF(Scenario="B",IF(R32="",P32,R32),P32))) | L32: =IF(OR($A32="",K32=""),"",IF(OR(F32="הושלם",F32="בוטל"),"",K32-Today_)) | M32: T-052 | N32: K | O32: 46392 | P32: 46420 | Q32: 46427 | R32: 46455 | T32: בחירת חומרים | U32: הנחה | V32: =IF(AND($A32<>"",F32<>"הושלם",F32<>"בוטל",J32<>""),IF(J32<=Today_+14,IF(K32="",99999,K32)+ROW()/100000,""),"") | W32: =IFERROR(IF($A32="","",CHOOSE(MATCH(G32,{"לא התחיל","בתהליך","ממתין","תקוע","באיחור","הושלם","בוטל"},0),1,2,3,3,4,5,6)*100000+IF(K32="",99999,K32)+ROW()/1000000),"") | X32: =IF(AND($A32<>"",F32<>"הושלם",F32<>"בוטל",OR(ISNUMBER(SEARCH("אריאל",D32)),D32="כל המשפחה")),IF(K32="",99999,K32)+ROW()/100000,"") | Y32: =IF(AND($A32<>"",F32<>"הושלם",F32<>"בוטל",OR(ISNUMBER(SEARCH("רינת",D32)),D32="כל המשפחה")),IF(K32="",99999,K32)+ROW()/100000,"") | Z32: =IF(AND($A32<>"",F32<>"הושלם",F32<>"בוטל",OR(ISNUMBER(SEARCH("תמר",D32)))),IF(K32="",99999,K32)+ROW()/100000,"") | AA32: =IF(AND($A32<>"",F32<>"הושלם",F32<>"בוטל",NOT(ISNUMBER(SEARCH("אריאל",D32))),NOT(ISNUMBER(SEARCH("רינת",D32))),NOT(ISNUMBER(SEARCH("תמר",D32))),D32<>"כל המשפחה"),IF(K32="",99999,K32)+ROW()/100000,"")
A33: T-054 | B33: 9 מסירה | C33: מסירה מקבלן ובדק | D33: אריאל+קבלן | E33: בינונית | F33: לא התחיל | G33: =IF($A33="","",IF(AND(F33<>"הושלם",F33<>"בוטל",K33<>"",K33<Today_),"באיחור",IF(F33="","לא התחיל",F33))) | I33: =IF($A33="","",IF(H33<>"",H33,IF(F33="הושלם",1,IF(F33="בתהליך",0.5,IF(OR(F33="ממתין",F33="תקוע"),0.25,0))))) | J33: =IF(OR($A33="",O33=""),"",IF(AND(N33="K",KeyActual<>""),O33+(KeyActual-KeyA),IF(Scenario="B",IF(Q33="",O33,Q33),O33))) | K33: =IF(OR($A33="",P33=""),"",IF(AND(N33="K",KeyActual<>""),P33+(KeyActual-KeyA),IF(Scenario="B",IF(R33="",P33,R33),P33))) | L33: =IF(OR($A33="",K33=""),"",IF(OR(F33="הושלם",F33="בוטל"),"",K33-Today_)) | M33: T-053 | N33: K | O33: 46420 | P33: 46427 | Q33: 46455 | R33: 46462 | S33: רשימת תיקונים | U33: הנחה | V33: =IF(AND($A33<>"",F33<>"הושלם",F33<>"בוטל",J33<>""),IF(J33<=Today_+14,IF(K33="",99999,K33)+ROW()/100000,""),"") | W33: =IFERROR(IF($A33="","",CHOOSE(MATCH(G33,{"לא התחיל","בתהליך","ממתין","תקוע","באיחור","הושלם","בוטל"},0),1,2,3,3,4,5,6)*100000+IF(K33="",99999,K33)+ROW()/1000000),"") | X33: =IF(AND($A33<>"",F33<>"הושלם",F33<>"בוטל",OR(ISNUMBER(SEARCH("אריאל",D33)),D33="כל המשפחה")),IF(K33="",99999,K33)+ROW()/100000,"") | Y33: =IF(AND($A33<>"",F33<>"הושלם",F33<>"בוטל",OR(ISNUMBER(SEARCH("רינת",D33)),D33="כל המשפחה")),IF(K33="",99999,K33)+ROW()/100000,"") | Z33: =IF(AND($A33<>"",F33<>"הושלם",F33<>"בוטל",OR(ISNUMBER(SEARCH("תמר",D33)))),IF(K33="",99999,K33)+ROW()/100000,"") | AA33: =IF(AND($A33<>"",F33<>"הושלם",F33<>"בוטל",NOT(ISNUMBER(SEARCH("אריאל",D33))),NOT(ISNUMBER(SEARCH("רינת",D33))),NOT(ISNUMBER(SEARCH("תמר",D33))),D33<>"כל המשפחה"),IF(K33="",99999,K33)+ROW()/100000,"")
A34: T-055 | B34: 6 גמר פנים | C34: מטבח: בחירת ספק והזמנה | D34: אריאל+רינת | E34: בינונית | F34: לא התחיל | G34: =IF($A34="","",IF(AND(F34<>"הושלם",F34<>"בוטל",K34<>"",K34<Today_),"באיחור",IF(F34="","לא התחיל",F34))) | I34: =IF($A34="","",IF(H34<>"",H34,IF(F34="הושלם",1,IF(F34="בתהליך",0.5,IF(OR(F34="ממתין",F34="תקוע"),0.25,0))))) | J34: =IF(OR($A34="",O34=""),"",IF(AND(N34="K",KeyActual<>""),O34+(KeyActual-KeyA),IF(Scenario="B",IF(Q34="",O34,Q34),O34))) | K34: =IF(OR($A34="",P34=""),"",IF(AND(N34="K",KeyActual<>""),P34+(KeyActual-KeyA),IF(Scenario="B",IF(R34="",P34,R34),P34))) | L34: =IF(OR($A34="",K34=""),"",IF(OR(F34="הושלם",F34="בוטל"),"",K34-Today_)) | M34: T-022 | N34: F | O34: 46341 | P34: 46376 | Q34: 46341 | R34: 46376 | S34: 3 הצעות; זמן אספקה טיפוסי 6–10 שבועות (הערכה, לאמת) | T34: מידות 319/470, מכשירים (למידות נגר) | U34: הזמנה מוקדמת ככל האפשר; מדידה סופית אחרי שלד | V34: =IF(AND($A34<>"",F34<>"הושלם",F34<>"בוטל",J34<>""),IF(J34<=Today_+14,IF(K34="",99999,K34)+ROW()/100000,""),"") | W34: =IFERROR(IF($A34="","",CHOOSE(MATCH(G34,{"לא התחיל","בתהליך","ממתין","תקוע","באיחור","הושלם","בוטל"},0),1,2,3,3,4,5,6)*100000+IF(K34="",99999,K34)+ROW()/1000000),"") | X34: =IF(AND($A34<>"",F34<>"הושלם",F34<>"בוטל",OR(ISNUMBER(SEARCH("אריאל",D34)),D34="כל המשפחה")),IF(K34="",99999,K34)+ROW()/100000,"") | Y34: =IF(AND($A34<>"",F34<>"הושלם",F34<>"בוטל",OR(ISNUMBER(SEARCH("רינת",D34)),D34="כל המשפחה")),IF(K34="",99999,K34)+ROW()/100000,"") | Z34: =IF(AND($A34<>"",F34<>"הושלם",F34<>"בוטל",OR(ISNUMBER(SEARCH("תמר",D34)))),IF(K34="",99999,K34)+ROW()/100000,"") | AA34: =IF(AND($A34<>"",F34<>"הושלם",F34<>"בוטל",NOT(ISNUMBER(SEARCH("אריאל",D34))),NOT(ISNUMBER(SEARCH("רינת",D34))),NOT(ISNUMBER(SEARCH("תמר",D34))),D34<>"כל המשפחה"),IF(K34="",99999,K34)+ROW()/100000,"")
A35: T-056 | B35: 6 גמר פנים | C35: ארונות קיר/חדר אורחים/ארונות במרפסת | D35: אריאל+רינת | E35: נמוכה | F35: לא התחיל | G35: =IF($A35="","",IF(AND(F35<>"הושלם",F35<>"בוטל",K35<>"",K35<Today_),"באיחור",IF(F35="","לא התחיל",F35))) | I35: =IF($A35="","",IF(H35<>"",H35,IF(F35="הושלם",1,IF(F35="בתהליך",0.5,IF(OR(F35="ממתין",F35="תקוע"),0.25,0))))) | J35: =IF(OR($A35="",O35=""),"",IF(AND(N35="K",KeyActual<>""),O35+(KeyActual-KeyA),IF(Scenario="B",IF(Q35="",O35,Q35),O35))) | K35: =IF(OR($A35="",P35=""),"",IF(AND(N35="K",KeyActual<>""),P35+(KeyActual-KeyA),IF(Scenario="B",IF(R35="",P35,R35),P35))) | L35: =IF(OR($A35="",K35=""),"",IF(OR(F35="הושלם",F35="בוטל"),"",K35-Today_)) | M35: T-020 | N35: F | O35: 46357 | P35: 46397 | Q35: 46357 | R35: 46397 | S35: תכנון והצעות | T35: מידות חדרים | U35: תלוי בסגירת מרפסת | V35: =IF(AND($A35<>"",F35<>"הושלם",F35<>"בוטל",J35<>""),IF(J35<=Today_+14,IF(K35="",99999,K35)+ROW()/100000,""),"") | W35: =IFERROR(IF($A35="","",CHOOSE(MATCH(G35,{"לא התחיל","בתהליך","ממתין","תקוע","באיחור","הושלם","בוטל"},0),1,2,3,3,4,5,6)*100000+IF(K35="",99999,K35)+ROW()/1000000),"") | X35: =IF(AND($A35<>"",F35<>"הושלם",F35<>"בוטל",OR(ISNUMBER(SEARCH("אריאל",D35)),D35="כל המשפחה")),IF(K35="",99999,K35)+ROW()/100000,"") | Y35: =IF(AND($A35<>"",F35<>"הושלם",F35<>"בוטל",OR(ISNUMBER(SEARCH("רינת",D35)),D35="כל המשפחה")),IF(K35="",99999,K35)+ROW()/100000,"") | Z35: =IF(AND($A35<>"",F35<>"הושלם",F35<>"בוטל",OR(ISNUMBER(SEARCH("תמר",D35)))),IF(K35="",99999,K35)+ROW()/100000,"") | AA35: =IF(AND($A35<>"",F35<>"הושלם",F35<>"בוטל",NOT(ISNUMBER(SEARCH("אריאל",D35))),NOT(ISNUMBER(SEARCH("רינת",D35))),NOT(ISNUMBER(SEARCH("תמר",D35))),D35<>"כל המשפחה"),IF(K35="",99999,K35)+ROW()/100000,"")
A36: T-057 | B36: 6 גמר פנים | C36: מדידה סופית בשטח לנגרות | D36: נגר/ספק מטבח | E36: בינונית | F36: לא התחיל | G36: =IF($A36="","",IF(AND(F36<>"הושלם",F36<>"בוטל",K36<>"",K36<Today_),"באיחור",IF(F36="","לא התחיל",F36))) | I36: =IF($A36="","",IF(H36<>"",H36,IF(F36="הושלם",1,IF(F36="בתהליך",0.5,IF(OR(F36="ממתין",F36="תקוע"),0.25,0))))) | J36: =IF(OR($A36="",O36=""),"",IF(AND(N36="K",KeyActual<>""),O36+(KeyActual-KeyA),IF(Scenario="B",IF(Q36="",O36,Q36),O36))) | K36: =IF(OR($A36="",P36=""),"",IF(AND(N36="K",KeyActual<>""),P36+(KeyActual-KeyA),IF(Scenario="B",IF(R36="",P36,R36),P36))) | L36: =IF(OR($A36="",K36=""),"",IF(OR(F36="הושלם",F36="בוטל"),"",K36-Today_)) | M36: T-051,T-052 | N36: K | O36: 46392 | P36: 46399 | Q36: 46427 | R36: 46434 | S36: אחרי טיח/ריצוף | U36: שינוי מידות = שינוי הזמנה | V36: =IF(AND($A36<>"",F36<>"הושלם",F36<>"בוטל",J36<>""),IF(J36<=Today_+14,IF(K36="",99999,K36)+ROW()/100000,""),"") | W36: =IFERROR(IF($A36="","",CHOOSE(MATCH(G36,{"לא התחיל","בתהליך","ממתין","תקוע","באיחור","הושלם","בוטל"},0),1,2,3,3,4,5,6)*100000+IF(K36="",99999,K36)+ROW()/1000000),"") | X36: =IF(AND($A36<>"",F36<>"הושלם",F36<>"בוטל",OR(ISNUMBER(SEARCH("אריאל",D36)),D36="כל המשפחה")),IF(K36="",99999,K36)+ROW()/100000,"") | Y36: =IF(AND($A36<>"",F36<>"הושלם",F36<>"בוטל",OR(ISNUMBER(SEARCH("רינת",D36)),D36="כל המשפחה")),IF(K36="",99999,K36)+ROW()/100000,"") | Z36: =IF(AND($A36<>"",F36<>"הושלם",F36<>"בוטל",OR(ISNUMBER(SEARCH("תמר",D36)))),IF(K36="",99999,K36)+ROW()/100000,"") | AA36: =IF(AND($A36<>"",F36<>"הושלם",F36<>"בוטל",NOT(ISNUMBER(SEARCH("אריאל",D36))),NOT(ISNUMBER(SEARCH("רינת",D36))),NOT(ISNUMBER(SEARCH("תמר",D36))),D36<>"כל המשפחה"),IF(K36="",99999,K36)+ROW()/100000,"")
A37: T-058 | B37: 6 גמר פנים | C37: התקנת מטבח וארונות | D37: ספק מטבח/נגר | E37: בינונית | F37: לא התחיל | G37: =IF($A37="","",IF(AND(F37<>"הושלם",F37<>"בוטל",K37<>"",K37<Today_),"באיחור",IF(F37="","לא התחיל",F37))) | I37: =IF($A37="","",IF(H37<>"",H37,IF(F37="הושלם",1,IF(F37="בתהליך",0.5,IF(OR(F37="ממתין",F37="תקוע"),0.25,0))))) | J37: =IF(OR($A37="",O37=""),"",IF(AND(N37="K",KeyActual<>""),O37+(KeyActual-KeyA),IF(Scenario="B",IF(Q37="",O37,Q37),O37))) | K37: =IF(OR($A37="",P37=""),"",IF(AND(N37="K",KeyActual<>""),P37+(KeyActual-KeyA),IF(Scenario="B",IF(R37="",P37,R37),P37))) | L37: =IF(OR($A37="",K37=""),"",IF(OR(F37="הושלם",F37="בוטל"),"",K37-Today_)) | M37: T-057 | N37: K | O37: 46413 | P37: 46434 | Q37: 46448 | R37: 46469 | U37: תלוי בזמן אספקה | V37: =IF(AND($A37<>"",F37<>"הושלם",F37<>"בוטל",J37<>""),IF(J37<=Today_+14,IF(K37="",99999,K37)+ROW()/100000,""),"") | W37: =IFERROR(IF($A37="","",CHOOSE(MATCH(G37,{"לא התחיל","בתהליך","ממתין","תקוע","באיחור","הושלם","בוטל"},0),1,2,3,3,4,5,6)*100000+IF(K37="",99999,K37)+ROW()/1000000),"") | X37: =IF(AND($A37<>"",F37<>"הושלם",F37<>"בוטל",OR(ISNUMBER(SEARCH("אריאל",D37)),D37="כל המשפחה")),IF(K37="",99999,K37)+ROW()/100000,"") | Y37: =IF(AND($A37<>"",F37<>"הושלם",F37<>"בוטל",OR(ISNUMBER(SEARCH("רינת",D37)),D37="כל המשפחה")),IF(K37="",99999,K37)+ROW()/100000,"") | Z37: =IF(AND($A37<>"",F37<>"הושלם",F37<>"בוטל",OR(ISNUMBER(SEARCH("תמר",D37)))),IF(K37="",99999,K37)+ROW()/100000,"") | AA37: =IF(AND($A37<>"",F37<>"הושלם",F37<>"בוטל",NOT(ISNUMBER(SEARCH("אריאל",D37))),NOT(ISNUMBER(SEARCH("רינת",D37))),NOT(ISNUMBER(SEARCH("תמר",D37))),D37<>"כל המשפחה"),IF(K37="",99999,K37)+ROW()/100000,"")
